<?xml version="1.0"?>
<robot name="myfirst">
    <link name="base_link">
        <visual>
            <geometry>
                <cylinder length="0.2" radius="0.1"/>
            </geometry>
            <material name="yellow">
                <color rgba="1 1 0 0.5"/>
            </material>
        </visual>
    </link>

  <link name="Left_wheel">
    <visual>
      <geometry>
        <cylinder length=".01" radius="0.0408"/>
      </geometry>
      <material name="blue"/>
    </visual>
  </link>

  <joint name="Left" type="continuous">
    <axis xyz="0 0 1"/>
    <parent link="base_link"/>
    <child link="Left_wheel"/>
    <origin rpy="1.57075 0 0" xyz="0 0.069 -0.085"/>
    <limit effort="100" velocity="100"/>
    <joint_properties damping="0.0" friction="0.0"/>
  </joint>
  
  <link name="Right_wheel">
    <visual>
      <geometry>
        <cylinder length=".01" radius="0.0408"/>
      </geometry>
      <material name="blue"/>
    </visual>
  </link>

  <joint name="Right" type="continuous">
    <axis xyz="0 0 1"/>
    <parent link="base_link"/>
    <child link="Right_wheel"/>
    <origin rpy="1.57075 0 0" xyz="0 -0.069 -0.085"/>
    <limit effort="100" velocity="100"/>
    <joint_properties damping="0.0" friction="0.0"/>
  </joint>

</robot>
